<?xml version="1.0" ?>

<robot name="arm" xmlns:xacro="http://www.ros.org/wiki/xacro">

  <xacro:include filename="$(find apsara)/urdf/1_d435.urdf.xacro" />

  <xacro:include filename="$(find apsara)/urdf/2_d435.urdf.xacro" />

     <!-- world will be root link-->
  <link name="world" />
   
  <joint name="world_joint" type="fixed">
    <parent link="world" />
    <child link = "pole_link" />
    <origin xyz="0.0 0.0 0.1" rpy="0.0 0.0 0.0" />
  </joint>

  <link name="pole_link">
    <visual>
      <geometry>
        <cylinder length="1.5" radius="0.1"/>
      </geometry>
    </visual>
  </link>

    <link name="base_link">
      <inertial>
        <mass value="500" />
        <origin rpy="0 0 0 " xyz="0 0 -0.0915" />
        <inertia ixx="0" ixy="0" ixz="0" iyy="0" iyz="0" izz="0" />
      </inertial>
      <collision>
        <origin rpy="0 0 0 " xyz="0 0 -0.0915" />
        <geometry>
          <box size="0.1 0.1 0.1" />
        </geometry>
      </collision>
      <visual>
        <origin rpy="0 0 0 " xyz="0 0 -0.0915" />
        <geometry>
          <box size="0.1 0.1 0.1" />
        </geometry>
      </visual>
    </link>
  

   <joint name="pole_joint" type="fixed">
      <parent link="pole_link" />
      <child link="base_link" />
      <origin xyz="0 0 0.75"/>
    </joint>


    <link name="link_01">
      <inertial>
        <mass value="157" />
        <origin rpy="0 0 0" xyz="0 0 0" />
        <inertia ixx="13.235" ixy="0" ixz="0" iyy="13.235" iyz="0" izz="9.655" />
      </inertial>
      <collision>
        <origin rpy="0 0 0" xyz="0 0 0" />
        <geometry>
          <mesh filename="package://apsara/meshes/link01.stl" scale="0.001 0.001 0.001"/>
        </geometry>
      </collision>
      <visual>
        <origin rpy="0 0 0" xyz="0 0 0" />
        <geometry>
          <mesh filename="package://apsara/meshes/link01.stl" scale="0.001 0.001 0.001"/>
        </geometry>
      </visual>
    </link>


       <joint name="base_link__link_01" type="revolute">
      <axis xyz="0 0 1" />
      <limit effort="1000" lower="-3.14" upper="3.14" velocity="0.5" />
      <origin rpy="0 0 0" xyz="0 0 0" />
      <parent link="base_link" />
      <child link="link_01" />
    </joint>
    <transmission name="trans_base_link__link_01">
      <type>transmission_interface/SimpleTransmission</type>
      <joint name="base_link__link_01">
        <hardwareInterface>hardware_interface/PositionJointInterface</hardwareInterface>
      </joint>
      <actuator name="motor_base_link__link_01">
        <hardwareInterface>hardware_interface/PositionJointInterface</hardwareInterface>
        <mechanicalReduction>1</mechanicalReduction>
      </actuator>
    </transmission>

    <joint name="link_01__link_02" type="revolute">
      <axis xyz="0 1 0" />
      <limit effort="1000" lower="-1.62" upper="1.62" velocity="0.5" />
      <origin rpy="0 0 0" xyz="0 0 0.1" />
      <parent link="link_01" />
      <child link="link_02" />
    </joint>
    <transmission name="trans_link_01__link_02">
      <type>transmission_interface/SimpleTransmission</type>
      <joint name="link_01__link_02">
        <hardwareInterface>hardware_interface/PositionJointInterface</hardwareInterface>
      </joint>
      <actuator name="motor_link_01__link_02">
        <hardwareInterface>hardware_interface/PositionJointInterface</hardwareInterface>
        <mechanicalReduction>1</mechanicalReduction>
      </actuator>
    </transmission>


    <link name="link_02">
      <inertial>
        <mass value="157" />
        <origin rpy="0 0 0" xyz="0 0 -0.1" />
        <inertia ixx="13.235" ixy="0" ixz="0" iyy="13.235" iyz="0" izz="9.655" />
      </inertial>
      <collision>
        <origin rpy="0 0 0" xyz="0 0 -0.1" />
        <geometry>
          <mesh filename="package://apsara/meshes/link12.stl" scale="0.001 0.001 0.001"/>
        </geometry>
      </collision>
      <visual>
        <origin rpy="0 0 0" xyz="0 0 -0.1" />
        <geometry>
          <mesh filename="package://apsara/meshes/link12.stl" scale="0.001 0.001 0.001"/>
        </geometry>
      </visual>
    </link>

    <joint name="link_02__link_03" type="revolute">
      <axis xyz="0 1 0" />
      <limit effort="1000" lower="-2.3" upper="2.3" velocity="0.5" />
      <origin rpy="0 0 0" xyz="0 0 0.299" />
      <parent link="link_02" />
      <child link="link_03" />
    </joint>
    <transmission name="trans_link_02__link_03">
      <type>transmission_interface/SimpleTransmission</type>
      <joint name="link_02__link_03">
        <hardwareInterface>hardware_interface/PositionJointInterface</hardwareInterface>
      </joint>
      <actuator name="motor_link_02__link_03">
        <hardwareInterface>hardware_interface/PositionJointInterface</hardwareInterface>
        <mechanicalReduction>1</mechanicalReduction>
      </actuator>
    </transmission>


    <link name="link_03">
      <inertial>
        <mass value="15" />
        <origin rpy="0 0 0" xyz="0 0 -0.399" />
        <inertia ixx="13.235" ixy="0" ixz="0" iyy="13.235" iyz="0" izz="9.655" />
      </inertial>
      <collision>
        <origin rpy="0 0 0" xyz="0 0 -0.399" />
        <geometry>
          <mesh filename="package://apsara/meshes/link23.stl" scale="0.001 0.001 0.001"/>
        </geometry>
      </collision>
      <visual>
        <origin rpy="0 0 0" xyz="0 0 -0.399" />
        <geometry>
          <mesh filename="package://apsara/meshes/link23.stl" scale="0.001 0.001 0.001"/>
        </geometry>
      </visual>
    </link>


    <joint name="link_03__link_04" type="revolute">
      <axis xyz="0 0 1" />
      <limit effort="1000" lower="-3.14" upper="3.14" velocity="0.5" />
      <origin rpy="0 0 0" xyz="0 0 0.1593" />
      <parent link="link_03" />
      <child link="link_04" />
    </joint>
    <transmission name="trans_link_03__link_04">
      <type>transmission_interface/SimpleTransmission</type>
      <joint name="link_03__link_04">
        <hardwareInterface>hardware_interface/PositionJointInterface</hardwareInterface>
      </joint>
      <actuator name="motor_link_03__link_04">
        <hardwareInterface>hardware_interface/PositionJointInterface</hardwareInterface>
        <mechanicalReduction>1</mechanicalReduction>
      </actuator>
    </transmission>


    <link name="link_04">
      <inertial>
        <mass value="15" />
        <origin rpy="0 0 0" xyz="0 0 -0.5592" />
        <inertia ixx="13.235" ixy="0" ixz="0" iyy="13.235" iyz="0" izz="9.655" />
      </inertial>
      <collision>
        <origin rpy="0 0 0" xyz="0 0 -0.5592" />
        <geometry>
          <mesh filename="package://apsara/meshes/link34.stl" scale="0.001 0.001 0.001"/>
        </geometry>
      </collision>
      <visual>
        <origin rpy="0 0 0" xyz="0 0 -0.5592" />
        <geometry>
          <mesh filename="package://apsara/meshes/link34.stl" scale="0.001 0.001 0.001"/>
        </geometry>
      </visual>
    </link>


      <joint name="link_04__link_05" type="revolute">
      <axis xyz="0 1 0" />
      <limit effort="1000" lower="-3.14" upper="3.14" velocity="0.5" />
      <origin rpy="0 0 0" xyz="0 0 0.1628" />
      <parent link="link_04" />
      <child link="link_05" />
    </joint>
    <transmission name="trans_link_04__link_05">
      <type>transmission_interface/SimpleTransmission</type>
      <joint name="link_04__link_05">
        <hardwareInterface>hardware_interface/PositionJointInterface</hardwareInterface>
      </joint>
      <actuator name="motor_link_04__link_05">
        <hardwareInterface>hardware_interface/PositionJointInterface</hardwareInterface>
        <mechanicalReduction>1</mechanicalReduction>
      </actuator>
    </transmission>

      <link name="link_05">
      <inertial>
        <mass value="15" />
        <origin rpy="0 0 0" xyz="0 0 -0.7085" />
        <inertia ixx="13.235" ixy="0" ixz="0" iyy="13.235" iyz="0" izz="9.655" />
      </inertial>
      <collision>
        <origin rpy="0 0 0" xyz="0 0 -0.7085" />
        <geometry>
          <mesh filename="package://apsara/meshes/link45.stl" scale="0.001 0.001 0.001"/>
        </geometry>
      </collision>
      <visual>
        <origin rpy="0 0 0" xyz="0 0 -0.7085" />
        <geometry>
          <mesh filename="package://apsara/meshes/link45.stl" scale="0.001 0.001 0.001"/>
        </geometry>
      </visual>
    </link>


    <joint name="link_05__link_06" type="revolute">
      <axis xyz="0 1 0" />
      <limit effort="1000" lower="-3.14" upper="3.14" velocity="0.5" />
      <origin rpy="0 0 0" xyz="0 0 0.1628" />
      <parent link="link_05" />
      <child link="link_06" />
    </joint>
    <transmission name="trans_link_05__link_06">
      <type>transmission_interface/SimpleTransmission</type>
      <joint name="link_05__link_06">
        <hardwareInterface>hardware_interface/PositionJointInterface</hardwareInterface>
      </joint>
      <actuator name="motor_link_05__link_06">
        <hardwareInterface>hardware_interface/PositionJointInterface</hardwareInterface>
        <mechanicalReduction>1</mechanicalReduction>
      </actuator>
    </transmission>

    <link name="link_06">
      <inertial>
        <mass value="5" />
        <origin rpy="0 0 0 " xyz="0 0 0.045" />
        <inertia ixx="170.667" ixy="0" ixz="0"
              iyy="170.667" iyz="0"
              izz="170.667" />
      </inertial>
      <collision>
        <origin rpy="0 0 0 " xyz="0 0 0.045" />
        <geometry>
          <box size="0.1 0.1 0.1" />
        </geometry>
      </collision>
      <visual>
        <origin rpy="0 0 0 " xyz="0 0 0.045" />
        <geometry>
          <box size="0.1 0.1 0.1" />
        </geometry>
      </visual>
    </link>
  
  <gazebo>
    <plugin name="gazebo_ros_control" filename="libgazebo_ros_control.so">
    </plugin>
  </gazebo>

  <link name="cam_pole_link">
    <visual>
      <geometry>
        <cylinder length="1" radius="0.03"/>
      </geometry>
    </visual>
  </link>

<joint name="cam_pole_joint" type="fixed">
      <parent link="world" />
      <child link="cam_pole_link" />
      <origin xyz="0 2 0.5"/>
</joint>

<sensor1_d435 parent="cam_pole_link">
    <origin xyz="0.0 0.0 0.5" rpy="0 0 -1.5708"/>
</sensor1_d435>

<link name="cam_pole_link2">
    <visual>
      <geometry>
        <cylinder length="1" radius="0.03"/>
      </geometry>
    </visual>
</link>

<joint name="cam_pole_joint2" type="fixed">
      <parent link="world" />
      <child link="cam_pole_link2" />
      <origin xyz="0 -2 0.5"/>
</joint>

<sensor2_d435 parent="cam_pole_link2">
    <origin xyz="0.0 0.0 0.5" rpy="0 0 1.5708"/>
</sensor2_d435>




</robot>
