<?xml version="1.0" ?>
<!-- =================================================================================== -->
<!-- |    This document was autogenerated by xacro from /home/sk/apsara/robov2_ws/src/apsara/urdf/mrm.xacro | -->
<!-- |    EDITING THIS FILE BY HAND IS NOT RECOMMENDED                                 | -->
<!-- =================================================================================== -->
<robot name="apsara" xmlns:xacro="http://www.ros.org/wiki/xacro">
    <!-- END - Include -->
    <link name="base_link">
        
<inertial>
            <mass value="0" />
            <origin rpy="0 0 0" xyz="0 0 -0.0915" />
            <inertia ixx="0" ixy="0" ixz="0" iyy="0" iyz="0" izz="0" />
        </inertial>

        <collision>
            <origin rpy="0 0 0" xyz="0 0 -0.0915" />
            <geometry>
                <box size="0.1 0.1 0.01" />
            </geometry>
        </collision>
        <visual>
            <origin rpy="0 0 0" xyz="0 0 -0.0915" />
            <geometry>
                <box size="0.1 0.1 0.01" />
            </geometry>
        </visual>
    </link>
    <joint name="base_link__link_01" type="revolute">
        <axis xyz="0 0 1" />
        <limit effort="1000" lower="-3.14" upper="3.14" velocity="0.5" />
        <origin rpy="0 0 0" xyz="0 0 -0.0915" />
        <parent link="base_link" />
        <child link="link_01" />
    </joint>
    <transmission name="trans_base_link__link_01">
        <type>transmission_interface/SimpleTransmission</type>
        <joint name="base_link__link_01">
            <hardwareInterface>hardware_interface/EffortJointInterface</hardwareInterface>
        </joint>
        <actuator name="motor_base_link__link_01">
            <hardwareInterface>hardware_interface/EffortJointInterface</hardwareInterface>
            <mechanicalReduction>1</mechanicalReduction>
        </actuator>
    </transmission>
    <link name="link_01">
        
<inertial>
            <mass value="157.633" />
            <origin rpy="0 0 0" xyz="0 0 0" />
            <inertia ixx="13.235" ixy="0" ixz="0" iyy="13.235" iyz="0" izz="9.655" />
        </inertial>

        <collision>
            <origin rpy="0 0 0" xyz="0 0 0" />
            <geometry>
                <mesh filename="package://apsara/meshes/link01.stl" scale="0.001 0.001 0.001" />
            </geometry>
        </collision>
        <visual>
            <origin rpy="0 0 0" xyz="0 0 0" />
            <geometry>
                <mesh filename="package://apsara/meshes/link01.stl" scale="0.001 0.001 0.001" />
            </geometry>
            <material name="light_black" />
        </visual>
    </link>
    <joint name="link_01__link_02" type="revolute">
        <axis xyz="0 1 0" />
        <limit effort="1000" lower="-1.62" upper="1.62" velocity="0.5" />
        <origin rpy="0 0 0" xyz="0 0 0.1" />
        <parent link="link_01" />
        <child link="link_02" />
    </joint>
    <transmission name="trans_link_01__link_02">
        <type>transmission_interface/SimpleTransmission</type>
        <joint name="link_01__link_02">
            <hardwareInterface>hardware_interface/EffortJointInterface</hardwareInterface>
        </joint>
        <actuator name="motor_link_01__link_02">
            <hardwareInterface>hardware_interface/EffortJointInterface</hardwareInterface>
            <mechanicalReduction>1</mechanicalReduction>
        </actuator>
    </transmission>
    <link name="link_02">
        
<inertial>
            <mass value="157.633" />
            <origin rpy="0 0 0" xyz="0 0 -0.1" />
            <inertia ixx="13.235" ixy="0" ixz="0" iyy="13.235" iyz="0" izz="9.655" />
        </inertial>

        <collision>
            <origin rpy="0 0 0" xyz="0 0 -0.1" />
            <geometry>
                <mesh filename="package://apsara/meshes/link12.stl" scale="0.001 0.001 0.001" />
            </geometry>
        </collision>
        <visual>
            <origin rpy="0 0 0" xyz="0 0 -0.1" />
            <geometry>
                <mesh filename="package://apsara/meshes/link12.stl" scale="0.001 0.001 0.001" />
            </geometry>
            <material name="light_black" />
        </visual>
    </link>
    <joint name="link_02__link_03" type="revolute">
        <axis xyz="0 1 0" />
        <limit effort="1000" lower="-2.3" upper="2.3" velocity="0.5" />
        <origin rpy="0 0 0" xyz="0 0 0.299" />
        <parent link="link_02" />
        <child link="link_03" />
    </joint>
    <transmission name="trans_link_02__link_03">
        <type>transmission_interface/SimpleTransmission</type>
        <joint name="link_02__link_03">
            <hardwareInterface>hardware_interface/EffortJointInterface</hardwareInterface>
        </joint>
        <actuator name="motor_link_02__link_03">
            <hardwareInterface>hardware_interface/EffortJointInterface</hardwareInterface>
            <mechanicalReduction>1</mechanicalReduction>
        </actuator>
    </transmission>
    <link name="link_03">
        
<inertial>
            <mass value="157.633" />
            <origin rpy="0 0 0" xyz="0 0 -0.399" />
            <inertia ixx="13.235" ixy="0" ixz="0" iyy="13.235" iyz="0" izz="9.655" />
        </inertial>

        <collision>
            <origin rpy="0 0 0" xyz="0 0 -0.399" />
            <geometry>
                <mesh filename="package://apsara/meshes/link23.stl" scale="0.001 0.001 0.001" />
            </geometry>
        </collision>
        <visual>
            <origin rpy="0 0 0" xyz="0 0 -0.399" />
            <geometry>
                <mesh filename="package://apsara/meshes/link23.stl" scale="0.001 0.001 0.001" />
            </geometry>
            <material name="light_black" />
        </visual>
    </link>
    <joint name="link_03__link_04" type="revolute">
        <axis xyz="0 0 1" />
        <limit effort="1000" lower="-3.14" upper="3.14" velocity="0.5" />
        <origin rpy="0 0 0" xyz="0 0 0.1593" />
        <parent link="link_03" />
        <child link="link_04" />
    </joint>
    <transmission name="trans_link_03__link_04">
        <type>transmission_interface/SimpleTransmission</type>
        <joint name="link_03__link_04">
            <hardwareInterface>hardware_interface/EffortJointInterface</hardwareInterface>
        </joint>
        <actuator name="motor_link_03__link_04">
            <hardwareInterface>hardware_interface/EffortJointInterface</hardwareInterface>
            <mechanicalReduction>1</mechanicalReduction>
        </actuator>
    </transmission>
    <link name="link_04">
        
<inertial>
            <mass value="157.633" />
            <origin rpy="0 0 0" xyz="0 0 -0.5592" />
            <inertia ixx="13.235" ixy="0" ixz="0" iyy="13.235" iyz="0" izz="9.655" />
        </inertial>

        <collision>
            <origin rpy="0 0 0" xyz="0 0 -0.5592" />
            <geometry>
                <mesh filename="package://apsara/meshes/link34.stl" scale="0.001 0.001 0.001" />
            </geometry>
        </collision>
        <visual>
            <origin rpy="0 0 0" xyz="0 0 -0.5592" />
            <geometry>
                <mesh filename="package://apsara/meshes/link34.stl" scale="0.001 0.001 0.001" />
            </geometry>
            <material name="light_black" />
        </visual>
    </link>
    <joint name="link_04__link_05" type="revolute">
        <axis xyz="0 1 0" />
        <limit effort="1000" lower="-2.24" upper="2.24" velocity="0.5" />
        <origin rpy="0 0 0" xyz="0 0 0.1493" />
        <parent link="link_04" />
        <child link="link_05" />
    </joint>
    <transmission name="trans_link_04__link_05">
        <type>transmission_interface/SimpleTransmission</type>
        <joint name="link_04__link_05">
            <hardwareInterface>hardware_interface/EffortJointInterface</hardwareInterface>
        </joint>
        <actuator name="motor_link_04__link_05">
            <hardwareInterface>hardware_interface/EffortJointInterface</hardwareInterface>
            <mechanicalReduction>1</mechanicalReduction>
        </actuator>
    </transmission>
    <link name="link_05">
        
<inertial>
            <mass value="157.633" />
            <origin rpy="0 0 0" xyz="0 0 -0.7085" />
            <inertia ixx="13.235" ixy="0" ixz="0" iyy="13.235" iyz="0" izz="9.655" />
        </inertial>

        <collision>
            <origin rpy="0 0 0" xyz="0 0 -0.7085" />
            <geometry>
                <mesh filename="package://apsara/meshes/link45.stl" scale="0.001 0.001 0.001" />
            </geometry>
        </collision>
        <visual>
            <origin rpy="0 0 0" xyz="0 0 -0.7085" />
            <geometry>
                <mesh filename="package://apsara/meshes/link45.stl" scale="0.001 0.001 0.001" />
            </geometry>
            <material name="light_black" />
        </visual>
    </link>
    <joint name="link_05__link_06" type="revolute">
        <axis xyz="0 0 1" />
        <limit effort="1000" lower="-3.14" upper="3.14" velocity="0.5" />
        <origin rpy="0 0 0" xyz="0 0 0.1628" />
        <parent link="link_05" />
        <child link="link_06" />
    </joint>
    <transmission name="trans_link_05__link_06">
        <type>transmission_interface/SimpleTransmission</type>
        <joint name="link_05__link_06">
            <hardwareInterface>hardware_interface/EffortJointInterface</hardwareInterface>
        </joint>
        <actuator name="motor_link_05__link_06">
            <hardwareInterface>hardware_interface/EffortJointInterface</hardwareInterface>
            <mechanicalReduction>1</mechanicalReduction>
        </actuator>
    </transmission>
    <link name="link_06">
        
<inertial>
            <mass value="1024" />
            <origin rpy="0 0 0" xyz="0 0 0.045" />
            <inertia ixx="170.667" ixy="0" ixz="0" iyy="170.667" iyz="0" izz="170.667" />
        </inertial>

        <collision>
            <origin rpy="0 0 0" xyz="0 0 0.045" />
            <geometry>
                <box size="0.1 0.1 0.1" />
            </geometry>
        </collision>
        <visual>
            <origin rpy="0 0 0" xyz="0 0 0.045" />
            <geometry>
                <box size="0.1 0.1 0.1" />
            </geometry>
        </visual>
    </link>
    <!-- END - Robot description -->
    <gazebo>
        <plugin filename="libgazebo_ros_control.so" name="gazebo_ros_control" />
    </gazebo>
    <transmission name="trans_base_link__link_01">
        <type>transmission_interface/SimpleTransmission</type>
        <joint name="base_link__link_01">
            <hardwareInterface>hardware_interface/PositionJointInterface</hardwareInterface>
        </joint>
        <actuator name="base_link__link_01_motor">
            <hardwareInterface>hardware_interface/PositionJointInterface</hardwareInterface>
            <mechanicalReduction>1</mechanicalReduction>
        </actuator>
    </transmission>
    <transmission name="trans_link_01__link_02">
        <type>transmission_interface/SimpleTransmission</type>
        <joint name="link_01__link_02">
            <hardwareInterface>hardware_interface/PositionJointInterface</hardwareInterface>
        </joint>
        <actuator name="link_01__link_02_motor">
            <hardwareInterface>hardware_interface/PositionJointInterface</hardwareInterface>
            <mechanicalReduction>1</mechanicalReduction>
        </actuator>
    </transmission>
    <transmission name="trans_link_02__link_03">
        <type>transmission_interface/SimpleTransmission</type>
        <joint name="link_02__link_03">
            <hardwareInterface>hardware_interface/PositionJointInterface</hardwareInterface>
        </joint>
        <actuator name="link_02__link_03_motor">
            <hardwareInterface>hardware_interface/PositionJointInterface</hardwareInterface>
            <mechanicalReduction>1</mechanicalReduction>
        </actuator>
    </transmission>
    <transmission name="trans_link_03__link_04">
        <type>transmission_interface/SimpleTransmission</type>
        <joint name="link_03__link_04">
            <hardwareInterface>hardware_interface/PositionJointInterface</hardwareInterface>
        </joint>
        <actuator name="link_03__link_04_motor">
            <hardwareInterface>hardware_interface/PositionJointInterface</hardwareInterface>
            <mechanicalReduction>1</mechanicalReduction>
        </actuator>
    </transmission>
    <transmission name="trans_link_04__link_05">
        <type>transmission_interface/SimpleTransmission</type>
        <joint name="link_04__link_05">
            <hardwareInterface>hardware_interface/PositionJointInterface</hardwareInterface>
        </joint>
        <actuator name="link_04__link_05_motor">
            <hardwareInterface>hardware_interface/PositionJointInterface</hardwareInterface>
            <mechanicalReduction>1</mechanicalReduction>
        </actuator>
    </transmission>
    <transmission name="trans_link_05__link_06">
        <type>transmission_interface/SimpleTransmission</type>
        <joint name="link_05__link_06">
            <hardwareInterface>hardware_interface/PositionJointInterface</hardwareInterface>
        </joint>
        <actuator name="link_05__link_06_motor">
            <hardwareInterface>hardware_interface/PositionJointInterface</hardwareInterface>
            <mechanicalReduction>1</mechanicalReduction>
        </actuator>
    </transmission>
    <gazebo>
        <plugin name="gazebo_ros_control" filename="libgazebo_ros_control.so">
            <robotNamespace>/</robotNamespace>
        </plugin>
    </gazebo>
</robot>

<transmission name="trans_base_link__link_01">
        <type>transmission_interface/SimpleTransmission</type>
        <joint name="base_link__link_01">
            <hardwareInterface>hardware_interface/EffortJointInterface</hardwareInterface>
        </joint>
        <actuator name="motor_base_link__link_01">
            <hardwareInterface>hardware_interface/EffortJointInterface</hardwareInterface>
            <mechanicalReduction>1</mechanicalReduction>
        </actuator>
    </transmission>
    <link name="link_01">
        <inertial>
            <mass value="157.633" />
            <origin rpy="0 0 0" xyz="0 0 0" />
            <inertia ixx="13.235" ixy="0" ixz="0" iyy="13.235" iyz="0" izz="9.655" />
        </inertial>
        <collision>
            <origin rpy="0 0 0" xyz="0 0 0" />
            <geometry>
                <mesh filename="package://apsara/meshes/link01.stl" scale="0.001 0.001 0.001" />
            </geometry>
        </collision>
        <visual>
            <origin rpy="0 0 0" xyz="0 0 0" />
            <geometry>
                <mesh filename="package://apsara/meshes/link01.stl" scale="0.001 0.001 0.001" />
            </geometry>
            <material name="light_black" />
        </visual>
    </link>
    <joint name="link_01__link_02" type="revolute">
        <axis xyz="0 1 0" />
        <limit effort="1000" lower="-1.62" upper="1.62" velocity="0.5" />
        <origin rpy="0 0 0" xyz="0 0 0.1" />
        <parent link="link_01" />
        <child link="link_02" />
    </joint>
    <transmission name="trans_link_01__link_02">
        <type>transmission_interface/SimpleTransmission</type>
        <joint name="link_01__link_02">
            <hardwareInterface>hardware_interface/EffortJointInterface</hardwareInterface>
        </joint>
        <actuator name="motor_link_01__link_02">
            <hardwareInterface>hardware_interface/EffortJointInterface</hardwareInterface>
            <mechanicalReduction>1</mechanicalReduction>
        </actuator>
    </transmission>
    <link name="link_02">
        <inertial>
            <mass value="157.633" />
            <origin rpy="0 0 0" xyz="0 0 -0.1" />
            <inertia ixx="13.235" ixy="0" ixz="0" iyy="13.235" iyz="0" izz="9.655" />
        </inertial>
        <collision>
            <origin rpy="0 0 0" xyz="0 0 -0.1" />
            <geometry>
                <mesh filename="package://apsara/meshes/link12.stl" scale="0.001 0.001 0.001" />
            </geometry>
        </collision>
        <visual>
            <origin rpy="0 0 0" xyz="0 0 -0.1" />
            <geometry>
                <mesh filename="package://apsara/meshes/link12.stl" scale="0.001 0.001 0.001" />
            </geometry>
            <material name="light_black" />
        </visual>
    </link>
    <joint name="link_02__link_03" type="revolute">
        <axis xyz="0 1 0" />
        <limit effort="1000" lower="-2.3" upper="2.3" velocity="0.5" />
        <origin rpy="0 0 0" xyz="0 0 0.299" />
        <parent link="link_02" />
        <child link="link_03" />
    </joint>
    <transmission name="trans_link_02__link_03">
        <type>transmission_interface/SimpleTransmission</type>
        <joint name="link_02__link_03">
            <hardwareInterface>hardware_interface/EffortJointInterface</hardwareInterface>
        </joint>
        <actuator name="motor_link_02__link_03">
            <hardwareInterface>hardware_interface/EffortJointInterface</hardwareInterface>
            <mechanicalReduction>1</mechanicalReduction>
        </actuator>
    </transmission>
    <link name="link_03">
        <inertial>
            <mass value="157.633" />
            <origin rpy="0 0 0" xyz="0 0 -0.399" />
            <inertia ixx="13.235" ixy="0" ixz="0" iyy="13.235" iyz="0" izz="9.655" />
        </inertial>
        <collision>
            <origin rpy="0 0 0" xyz="0 0 -0.399" />
            <geometry>
                <mesh filename="package://apsara/meshes/link23.stl" scale="0.001 0.001 0.001" />
            </geometry>
        </collision>
        <visual>
            <origin rpy="0 0 0" xyz="0 0 -0.399" />
            <geometry>
                <mesh filename="package://apsara/meshes/link23.stl" scale="0.001 0.001 0.001" />
            </geometry>
            <material name="light_black" />
        </visual>
    </link>
    <joint name="link_03__link_04" type="revolute">
        <axis xyz="0 0 1" />
        <limit effort="1000" lower="-3.14" upper="3.14" velocity="0.5" />
        <origin rpy="0 0 0" xyz="0 0 0.1593" />
        <parent link="link_03" />
        <child link="link_04" />
    </joint>
    <transmission name="trans_link_03__link_04">
        <type>transmission_interface/SimpleTransmission</type>
        <joint name="link_03__link_04">
            <hardwareInterface>hardware_interface/EffortJointInterface</hardwareInterface>
        </joint>
        <actuator name="motor_link_03__link_04">
            <hardwareInterface>hardware_interface/EffortJointInterface</hardwareInterface>
            <mechanicalReduction>1</mechanicalReduction>
        </actuator>
    </transmission>
    <link name="link_04">
        <inertial>
            <mass value="157.633" />
            <origin rpy="0 0 0" xyz="0 0 -0.5592" />
            <inertia ixx="13.235" ixy="0" ixz="0" iyy="13.235" iyz="0" izz="9.655" />
        </inertial>
        <collision>
            <origin rpy="0 0 0" xyz="0 0 -0.5592" />
            <geometry>
                <mesh filename="package://apsara/meshes/link34.stl" scale="0.001 0.001 0.001" />
            </geometry>
        </collision>
        <visual>
            <origin rpy="0 0 0" xyz="0 0 -0.5592" />
            <geometry>
                <mesh filename="package://apsara/meshes/link34.stl" scale="0.001 0.001 0.001" />
            </geometry>
            <material name="light_black" />
        </visual>
    </link>
    <joint name="link_04__link_05" type="revolute">
        <axis xyz="0 1 0" />
        <limit effort="1000" lower="-2.24" upper="2.24" velocity="0.5" />
        <origin rpy="0 0 0" xyz="0 0 0.1493" />
        <parent link="link_04" />
        <child link="link_05" />
    </joint>
    <transmission name="trans_link_04__link_05">
        <type>transmission_interface/SimpleTransmission</type>
        <joint name="link_04__link_05">
            <hardwareInterface>hardware_interface/EffortJointInterface</hardwareInterface>
        </joint>
        <actuator name="motor_link_04__link_05">
            <hardwareInterface>hardware_interface/EffortJointInterface</hardwareInterface>
            <mechanicalReduction>1</mechanicalReduction>
        </actuator>
    </transmission>
    <link name="link_05">
        <inertial>
            <mass value="157.633" />
            <origin rpy="0 0 0" xyz="0 0 -0.7085" />
            <inertia ixx="13.235" ixy="0" ixz="0" iyy="13.235" iyz="0" izz="9.655" />
        </inertial>
        <collision>
            <origin rpy="0 0 0" xyz="0 0 -0.7085" />
            <geometry>
                <mesh filename="package://apsara/meshes/link45.stl" scale="0.001 0.001 0.001" />
            </geometry>
        </collision>
        <visual>
            <origin rpy="0 0 0" xyz="0 0 -0.7085" />
            <geometry>
                <mesh filename="package://apsara/meshes/link45.stl" scale="0.001 0.001 0.001" />
            </geometry>
            <material name="light_black" />
        </visual>
    </link>
    <joint name="link_05__link_06" type="revolute">
        <axis xyz="0 0 1" />
        <limit effort="1000" lower="-3.14" upper="3.14" velocity="0.5" />
        <origin rpy="0 0 0" xyz="0 0 0.1628" />
        <parent link="link_05" />
        <child link="link_06" />
    </joint>
    <transmission name="trans_link_05__link_06">
        <type>transmission_interface/SimpleTransmission</type>
        <joint name="link_05__link_06">
            <hardwareInterface>hardware_interface/EffortJointInterface</hardwareInterface>
        </joint>
        <actuator name="motor_link_05__link_06">
            <hardwareInterface>hardware_interface/EffortJointInterface</hardwareInterface>
            <mechanicalReduction>1</mechanicalReduction>
        </actuator>
    </transmission>
    <link name="link_06">
        <inertial>
            <mass value="1024" />
            <origin rpy="0 0 0" xyz="0 0 0.045" />
            <inertia ixx="170.667" ixy="0" ixz="0" iyy="170.667" iyz="0" izz="170.667" />
        </inertial>
        <collision>
            <origin rpy="0 0 0" xyz="0 0 0.045" />
            <geometry>
                <box size="0.1 0.1 0.1" />
            </geometry>
        </collision>
        <visual>
            <origin rpy="0 0 0" xyz="0 0 0.045" />
            <geometry>
                <box size="0.1 0.1 0.1" />
            </geometry>
        </visual>
    </link>
    <!-- END - Robot description -->
    <gazebo>
        <plugin filename="libgazebo_ros_control.so" name="gazebo_ros_control" />
    </gazebo>
    <transmission name="trans_base_link__link_01">
        <type>transmission_interface/SimpleTransmission</type>
        <joint name="base_link__link_01">
            <hardwareInterface>hardware_interface/PositionJointInterface</hardwareInterface>
        </joint>
        <actuator name="base_link__link_01_motor">
            <hardwareInterface>hardware_interface/PositionJointInterface</hardwareInterface>
            <mechanicalReduction>1</mechanicalReduction>
        </actuator>
    </transmission>
    <transmission name="trans_link_01__link_02">
        <type>transmission_interface/SimpleTransmission</type>
        <joint name="link_01__link_02">
            <hardwareInterface>hardware_interface/PositionJointInterface</hardwareInterface>
        </joint>
        <actuator name="link_01__link_02_motor">
            <hardwareInterface>hardware_interface/PositionJointInterface</hardwareInterface>
            <mechanicalReduction>1</mechanicalReduction>
        </actuator>
    </transmission>
    <transmission name="trans_link_02__link_03">
        <type>transmission_interface/SimpleTransmission</type>
        <joint name="link_02__link_03">
            <hardwareInterface>hardware_interface/PositionJointInterface</hardwareInterface>
        </joint>
        <actuator name="link_02__link_03_motor">
            <hardwareInterface>hardware_interface/PositionJointInterface</hardwareInterface>
            <mechanicalReduction>1</mechanicalReduction>
        </actuator>
    </transmission>
    <transmission name="trans_link_03__link_04">
        <type>transmission_interface/SimpleTransmission</type>
        <joint name="link_03__link_04">
            <hardwareInterface>hardware_interface/PositionJointInterface</hardwareInterface>
        </joint>
        <actuator name="link_03__link_04_motor">
            <hardwareInterface>hardware_interface/PositionJointInterface</hardwareInterface>
            <mechanicalReduction>1</mechanicalReduction>
        </actuator>
    </transmission>
    <transmission name="trans_link_04__link_05">
        <type>transmission_interface/SimpleTransmission</type>
        <joint name="link_04__link_05">
            <hardwareInterface>hardware_interface/PositionJointInterface</hardwareInterface>
        </joint>
        <actuator name="link_04__link_05_motor">
            <hardwareInterface>hardware_interface/PositionJointInterface</hardwareInterface>
            <mechanicalReduction>1</mechanicalReduction>
        </actuator>
    </transmission>
    <transmission name="trans_link_05__link_06">
        <type>transmission_interface/SimpleTransmission</type>
        <joint name="link_05__link_06">
            <hardwareInterface>hardware_interface/PositionJointInterface</hardwareInterface>
        </joint>
        <actuator name="link_05__link_06_motor">
            <hardwareInterface>hardware_interface/PositionJointInterface</hardwareInterface>
            <mechanicalReduction>1</mechanicalReduction>
        </actuator>
    </transmission>
    <gazebo>
        <plugin name="gazebo_ros_control" filename="libgazebo_ros_control.so">
            <robotNamespace>/</robotNamespace>
        </plugin>
    </gazebo>
</robot>